<?xml version="1.0" encoding="utf-8"?>
<robot
  name="vehicle_urdf_updated">
  <link
    name="base_link">
    <inertial>
      <origin
        xyz="0.633646238955482 0.380995985063104 0.134713561280758"
        rpy="0 0 0" />
      <mass
        value="40.8578739183061" />
      <inertia
        ixx="0.995761028354978"
        ixy="-8.76320048207689E-06"
        ixz="0.00865884640055963"
        iyy="2.14944321692204"
        iyz="1.27940269792283E-05"
        izz="2.95983860146672" />
    </inertial>
    <visual>
      <origin
        xyz="0 0 0"
        rpy="0 0 0" />
      <geometry>
        <mesh
          filename="package://vehicle_urdf_updated/meshes/base_link.STL" />
      </geometry>
      <material
        name="">
        <color
          rgba="1 0 0 1" />
      </material>
    </visual>
    <collision>
      <origin
        xyz="0 0 0"
        rpy="0 0 0" />
      <geometry>
        <mesh
          filename="package://vehicle_urdf_updated/meshes/base_link.STL" />
      </geometry>
    </collision>
  </link>
  <link
    name="rear_transmission">
    <inertial>
      <origin
        xyz="-0.203199999999985 5.82867087928207E-16 8.21565038222616E-15"
        rpy="0 0 0" />
      <mass
        value="1.62545461137797" />
      <inertia
        ixx="0.00275735422572006"
        ixy="-2.88882404288101E-18"
        ixz="9.55642867448498E-19"
        iyy="0.0414194977112141"
        iyz="9.24865283108885E-09"
        izz="0.0414191060690131" />
    </inertial>
    <visual>
      <origin
        xyz="0 0 0"
        rpy="0 0 0" />
      <geometry>
        <mesh
          filename="package://vehicle_urdf_updated/meshes/rear_transmission.STL" />
      </geometry>
      <material
        name="">
        <color
          rgba="0.792156862745098 0.819607843137255 0.933333333333333 1" />
      </material>
    </visual>
    <collision>
      <origin
        xyz="0 0 0"
        rpy="0 0 0" />
      <geometry>
        <mesh
          filename="package://vehicle_urdf_updated/meshes/rear_transmission.STL" />
      </geometry>
    </collision>
  </link>
  <joint
    name="rear_transmission_joint"
    type="continuous">
    <origin
      xyz="0.3556 0.1778 0.0635"
      rpy="-1.5708 0 -1.5708" />
    <parent
      link="base_link" />
    <child
      link="rear_transmission" />
    <axis
      xyz="1 0 0" />
  </joint>
  <link
    name="front_left_pivot">
    <inertial>
      <origin
        xyz="0.0419537233296554 0.0535456913177643 -1.79199277638986E-09"
        rpy="0 0 0" />
      <mass
        value="0.342307075044178" />
      <inertia
        ixx="0.000402629200989729"
        ixy="0.000289839368110352"
        ixz="-3.70439072569397E-11"
        iyy="0.000794160741830236"
        iyz="-6.47936725203429E-14"
        izz="0.00107762693577772" />
    </inertial>
    <visual>
      <origin
        xyz="0 0 0"
        rpy="0 0 0" />
      <geometry>
        <mesh
          filename="package://vehicle_urdf_updated/meshes/front_left_pivot.STL" />
      </geometry>
      <material
        name="">
        <color
          rgba="0.792156862745098 0.819607843137255 0.933333333333333 1" />
      </material>
    </visual>
    <collision>
      <origin
        xyz="0 0 0"
        rpy="0 0 0" />
      <geometry>
        <mesh
          filename="package://vehicle_urdf_updated/meshes/front_left_pivot.STL" />
      </geometry>
    </collision>
  </link>
  <joint
    name="front_left_pivot_joint"
    type="continuous">
    <origin
      xyz="0.8636 0.4572 0.030137"
      rpy="1.5708 0 1.5708" />
    <parent
      link="base_link" />
    <child
      link="front_left_pivot" />
    <axis
      xyz="0 1 0" />
  </joint>
  <link
    name="front_left_wheel">
    <inertial>
      <origin
        xyz="0.0253999999999999 -1.11022302462516E-16 2.77555756156289E-17"
        rpy="0 0 0" />
      <mass
        value="0.555000200309947" />
      <inertia
        ixx="0.001204932765174"
        ixy="7.58500037625292E-20"
        ixz="5.19358445636026E-20"
        iyy="0.000713183485157935"
        iyz="2.71050543121376E-20"
        izz="0.000713183485157934" />
    </inertial>
    <visual>
      <origin
        xyz="0 0 0"
        rpy="0 0 0" />
      <geometry>
        <mesh
          filename="package://vehicle_urdf_updated/meshes/front_left_wheel.STL" />
      </geometry>
      <material
        name="">
        <color
          rgba="0.792156862745098 0.819607843137255 0.933333333333333 1" />
      </material>
    </visual>
    <collision>
      <origin
        xyz="0 0 0"
        rpy="0 0 0" />
      <geometry>
        <mesh
          filename="package://vehicle_urdf_updated/meshes/front_left_wheel.STL" />
      </geometry>
    </collision>
  </link>
  <joint
    name="front_left_wheel_joint"
    type="continuous">
    <origin
      xyz="0.0635 0.033363 0"
      rpy="1.432 0 0" />
    <parent
      link="front_left_pivot" />
    <child
      link="front_left_wheel" />
    <axis
      xyz="1 0 0" />
  </joint>
  <link
    name="front_right_pivot">
    <inertial>
      <origin
        xyz="0.0419537233296554 -0.0535456913177643 1.79199277638986E-09"
        rpy="0 0 0" />
      <mass
        value="0.342307075044179" />
      <inertia
        ixx="0.000402629200989729"
        ixy="-0.000289839368110352"
        ixz="3.70439077980642E-11"
        iyy="0.000794160741830237"
        iyz="-6.47936358096042E-14"
        izz="0.00107762693577773" />
    </inertial>
    <visual>
      <origin
        xyz="0 0 0"
        rpy="0 0 0" />
      <geometry>
        <mesh
          filename="package://vehicle_urdf_updated/meshes/front_right_pivot.STL" />
      </geometry>
      <material
        name="">
        <color
          rgba="0.792156862745098 0.819607843137255 0.933333333333333 1" />
      </material>
    </visual>
    <collision>
      <origin
        xyz="0 0 0"
        rpy="0 0 0" />
      <geometry>
        <mesh
          filename="package://vehicle_urdf_updated/meshes/front_right_pivot.STL" />
      </geometry>
    </collision>
  </link>
  <joint
    name="front_right_pivot_joint"
    type="continuous">
    <origin
      xyz="0.8636 0.3048 0.030137"
      rpy="-1.5708 0 -1.5708" />
    <parent
      link="base_link" />
    <child
      link="front_right_pivot" />
    <axis
      xyz="0 1 0" />
  </joint>
  <link
    name="front_right_wheel">
    <inertial>
      <origin
        xyz="-0.0254 1.11022302462516E-16 -1.11022302462516E-16"
        rpy="0 0 0" />
      <mass
        value="0.555000200309947" />
      <inertia
        ixx="0.001204932765174"
        ixy="4.1822253051509E-20"
        ixz="-7.14033442007878E-20"
        iyy="0.000713183485157937"
        iyz="-1.35525271560688E-19"
        izz="0.000713183485157937" />
    </inertial>
    <visual>
      <origin
        xyz="0 0 0"
        rpy="0 0 0" />
      <geometry>
        <mesh
          filename="package://vehicle_urdf_updated/meshes/front_right_wheel.STL" />
      </geometry>
      <material
        name="">
        <color
          rgba="0.792156862745098 0.819607843137255 0.933333333333333 1" />
      </material>
    </visual>
    <collision>
      <origin
        xyz="0 0 0"
        rpy="0 0 0" />
      <geometry>
        <mesh
          filename="package://vehicle_urdf_updated/meshes/front_right_wheel.STL" />
      </geometry>
    </collision>
  </link>
  <joint
    name="front_right_wheel_joint"
    type="continuous">
    <origin
      xyz="0.0635 -0.033363 0"
      rpy="2.1463 0 3.1416" />
    <parent
      link="front_right_pivot" />
    <child
      link="front_right_wheel" />
    <axis
      xyz="1 0 0" />
  </joint>
</robot>
